<inh f='include/c++/4.9/exception' l='60' c='std::exception'/>
<def f='include/c++/4.9/stdexcept' l='112'/>
<ovr f='include/c++/4.9/stdexcept' l='130' c='std::range_error'/>
<ovr f='include/c++/4.9/stdexcept' l='138' c='std::overflow_error'/>
<ovr f='include/c++/4.9/stdexcept' l='146' c='std::underflow_error'/>
<ovr f='TrinityCore3.3.5/dep/cppformat/format.h' l='488' c='fmt::FormatError'/>
<ovr f='TrinityCore3.3.5/dep/cppformat/format.h' l='1332' c='fmt::internal::RuntimeError'/>
<size>16</size>
<doc f='include/c++/4.9/stdexcept' l='107'>/** Runtime errors represent problems outside the scope of a program;
   *  they cannot be easily predicted and can generally only be caught as
   *  the program executes.
   *  @brief One of two subclasses of exception.
   */</doc>
<ovr f='include/c++/4.9/system_error' l='312' c='std::system_error'/>
<ovr f='include/boost/system/system_error.hpp' l='22' c='boost::system::system_error'/>
<ovr f='include/boost/property_tree/exceptions.hpp' l='27' c='boost::property_tree::ptree_error'/>
<ovr f='TrinityCore6.x/dep/cppformat/format.h' l='488' c='fmt::FormatError'/>
<ovr f='TrinityCore6.x/dep/cppformat/format.h' l='1332' c='fmt::internal::RuntimeError'/>
<ovr f='include/boost/function/function_base.hpp' l='739' c='boost::bad_function_call'/>
